<?xml version="1.0" ?>
<robot name="urdf_2">
<link name="base_link">
  <inertial>
    <origin rpy="0 0 0" xyz="-0.0 -3.3e-05 0.025"/>
    <mass value="35.321242"/>
    <inertia ixx="0.333824" ixy="-0.0" ixz="2.9e-05" iyy="0.222402" iyz="-2.9e-05" izz="0.541521"/>
  </inertial>
  <visual>
    <origin rpy="0 0 0" xyz="0 0 0"/>
    <geometry>
      <mesh filename="package://fusion2urdf/urdf_2/bin_stl/base_link_m-binary.stl"/>
    </geometry>
    <material name="silver">
      <color rgba="1 0 0 1"/>
    </material>
  </visual>
  <collision>
    <origin rpy="0 0 0" xyz="0 0 0"/>
    <geometry>
      <mesh filename="package://fusion2urdf/urdf_2/bin_stl/base_link_m-binary.stl"/>
    </geometry>
  </collision>
</link>
<link name="teker1_1">
  <inertial>
    <origin rpy="0 0 0" xyz="0.0121 0.0 0.0"/>
    <mass value="0.527579"/>
    <inertia ixx="0.000242" ixy="-0.0" ixz="0.003767" iyy="0.000147" iyz="-0.003767" izz="0.000147"/>
  </inertial>
  <visual>
    <origin rpy="0 0 0" xyz="-0.135 0.1385 -0.025"/>
    <geometry>
      <mesh filename="package://fusion2urdf/urdf_2/bin_stl/teker1_1_m-binary.stl"/>
    </geometry>
    <material name="silver">
      <color rgba="1 0 0 1"/>
    </material>
  </visual>
  <collision>
    <origin rpy="0 0 0" xyz="-0.135 0.1385 -0.025"/>
    <geometry>
      <mesh filename="package://fusion2urdf/urdf_2/bin_stl/teker1_1_m-binary.stl"/>
    </geometry>
  </collision>
</link>
<link name="teker3_1">
  <inertial>
    <origin rpy="0 0 0" xyz="-0.0121 0.0 0.0"/>
    <mass value="0.527579"/>
    <inertia ixx="0.000242" ixy="-0.0" ixz="-0.002791" iyy="0.000147" iyz="0.002791" izz="0.000147"/>
  </inertial>
  <visual>
    <origin rpy="0 0 0" xyz="0.135 -0.0645 -0.025"/>
    <geometry>
      <mesh filename="package://fusion2urdf/urdf_2/bin_stl/teker3_1_m-binary.stl"/>
    </geometry>
    <material name="silver">
      <color rgba="1 0 0 1"/>
    </material>
  </visual>
  <collision>
    <origin rpy="0 0 0" xyz="0.135 -0.0645 -0.025"/>
    <geometry>
      <mesh filename="package://fusion2urdf/urdf_2/bin_stl/teker3_1_m-binary.stl"/>
    </geometry>
  </collision>
</link>
<link name="teker4_1">
  <inertial>
    <origin rpy="0 0 0" xyz="-0.0121 0.0 0.0"/>
    <mass value="0.527579"/>
    <inertia ixx="0.000242" ixy="0.0" ixz="-0.000113" iyy="0.000147" iyz="0.000113" izz="0.000147"/>
  </inertial>
  <visual>
    <origin rpy="0 0 0" xyz="0.135 0.1385 -0.025"/>
    <geometry>
      <mesh filename="package://fusion2urdf/urdf_2/bin_stl/teker4_1_m-binary.stl"/>
    </geometry>
    <material name="silver">
      <color rgba="1 0 0 1"/>
    </material>
  </visual>
  <collision>
    <origin rpy="0 0 0" xyz="0.135 0.1385 -0.025"/>
    <geometry>
      <mesh filename="package://fusion2urdf/urdf_2/bin_stl/teker4_1_m-binary.stl"/>
    </geometry>
  </collision>
</link>
<link name="teker2_1">
  <inertial>
    <origin rpy="0 0 0" xyz="0.0121 0.0 0.0"/>
    <mass value="0.527579"/>
    <inertia ixx="0.000242" ixy="0.0" ixz="0.001089" iyy="0.000147" iyz="-0.001089" izz="0.000147"/>
  </inertial>
  <visual>
    <origin rpy="0 0 0" xyz="-0.135 -0.0645 -0.025"/>
    <geometry>
      <mesh filename="package://fusion2urdf/urdf_2/bin_stl/teker2_1_m-binary.stl"/>
    </geometry>
    <material name="silver">
      <color rgba="1 0 0 1"/>
    </material>
  </visual>
  <collision>
    <origin rpy="0 0 0" xyz="-0.135 -0.0645 -0.025"/>
    <geometry>
      <mesh filename="package://fusion2urdf/urdf_2/bin_stl/teker2_1_m-binary.stl"/>
    </geometry>
  </collision>
</link>
<joint name="Rev2" type="continuous">
  <origin rpy="0 0 0" xyz="0.135 -0.1385 0.025"/>
  <parent link="base_link"/>
  <child link="teker1_1"/>
  <axis xyz="-0.01 0.0 0.0"/>
</joint>
<transmission name="Rev2_tran">
  <type>transmission_interface/SimpleTransmission</type>
  <joint name="Rev2">
    <hardwareInterface>PositionJointInterface</hardwareInterface>
  </joint>
  <actuator name="Rev2_actr">
    <hardwareInterface>PositionJointInterface</hardwareInterface>
    <mechanicalReduction>1</mechanicalReduction>
  </actuator>
</transmission>
<joint name="Rev3" type="continuous">
  <origin rpy="0 0 0" xyz="-0.135 0.0645 0.025"/>
  <parent link="base_link"/>
  <child link="teker3_1"/>
  <axis xyz="0.01 0.0 0.0"/>
</joint>
<transmission name="Rev3_tran">
  <type>transmission_interface/SimpleTransmission</type>
  <joint name="Rev3">
    <hardwareInterface>PositionJointInterface</hardwareInterface>
  </joint>
  <actuator name="Rev3_actr">
    <hardwareInterface>PositionJointInterface</hardwareInterface>
    <mechanicalReduction>1</mechanicalReduction>
  </actuator>
</transmission>
<joint name="Rev4" type="continuous">
  <origin rpy="0 0 0" xyz="-0.135 -0.1385 0.025"/>
  <parent link="base_link"/>
  <child link="teker4_1"/>
  <axis xyz="0.01 0.0 0.0"/>
</joint>
<transmission name="Rev4_tran">
  <type>transmission_interface/SimpleTransmission</type>
  <joint name="Rev4">
    <hardwareInterface>PositionJointInterface</hardwareInterface>
  </joint>
  <actuator name="Rev4_actr">
    <hardwareInterface>PositionJointInterface</hardwareInterface>
    <mechanicalReduction>1</mechanicalReduction>
  </actuator>
</transmission>
<joint name="Rev1" type="continuous">
  <origin rpy="0 0 0" xyz="0.135 0.0645 0.025"/>
  <parent link="base_link"/>
  <child link="teker2_1"/>
  <axis xyz="-0.01 0.0 0.0"/>
</joint>
<transmission name="Rev1_tran">
  <type>transmission_interface/SimpleTransmission</type>
  <joint name="Rev1">
    <hardwareInterface>PositionJointInterface</hardwareInterface>
  </joint>
  <actuator name="Rev1_actr">
    <hardwareInterface>PositionJointInterface</hardwareInterface>
    <mechanicalReduction>1</mechanicalReduction>
  </actuator>
</transmission>
<gazebo>
  <plugin filename="libgazebo_ros_control.so" name="control"/>
</gazebo>
</robot>
